Workbook

Sheet Resumen
A1: RED DE COLEGIOS MANO AMIGA · CUMPLIMIENTO NORMATIVO
A2: DOCUMENTOS PARA CONVOCATORIAS
A3: Checklist contra el Catálogo de Cumplimiento del Sistema RCMA · 28/10/2026
A5: DOCUMENTOS QUE PIDEN | B5: EN EL SISTEMA | C5: PARCIAL | D5: NO ESTÁN | E5: COBERTURA (SÍ + ½ PARCIAL)
A6: =COUNTA(Checklist!$C$8:$C$75) | B6: =COUNTIF(Checklist!$D$8:$D$75,"Sí") | C6: =COUNTIF(Checklist!$D$8:$D$75,"Parcial") | D6: =COUNTIF(Checklist!$D$8:$D$75,"No") | E6: =IFERROR((B6+C6/2)/A6,0)
A8: AVANCE POR CATEGORÍA
A9: Categoría | B9: Documentos | C9: En el sistema | D9: Parcial | E9: No están | F9: Cobertura
A10: Documentación legal | B10: =COUNTIFS(Checklist!$B$8:$B$75,"DOCUMENTACIÓN LEGAL",Checklist!$C$8:$C$75,"<>") | C10: =COUNTIFS(Checklist!$B$8:$B$75,"DOCUMENTACIÓN LEGAL",Checklist!$D$8:$D$75,"Sí") | D10: =COUNTIFS(Checklist!$B$8:$B$75,"DOCUMENTACIÓN LEGAL",Checklist!$D$8:$D$75,"Parcial") | E10: =COUNTIFS(Checklist!$B$8:$B$75,"DOCUMENTACIÓN LEGAL",Checklist!$D$8:$D$75,"No") | F10: =IFERROR((C10+D10/2)/B10,0)
A11: Documentación fiscal | B11: =COUNTIFS(Checklist!$B$8:$B$75,"DOCUMENTACIÓN FISCAL",Checklist!$C$8:$C$75,"<>") | C11: =COUNTIFS(Checklist!$B$8:$B$75,"DOCUMENTACIÓN FISCAL",Checklist!$D$8:$D$75,"Sí") | D11: =COUNTIFS(Checklist!$B$8:$B$75,"DOCUMENTACIÓN FISCAL",Checklist!$D$8:$D$75,"Parcial") | E11: =COUNTIFS(Checklist!$B$8:$B$75,"DOCUMENTACIÓN FISCAL",Checklist!$D$8:$D$75,"No") | F11: =IFERROR((C11+D11/2)/B11,0)
A12: Documentación contable | B12: =COUNTIFS(Checklist!$B$8:$B$75,"DOCUMENTACIÓN CONTABLE",Checklist!$C$8:$C$75,"<>") | C12: =COUNTIFS(Checklist!$B$8:$B$75,"DOCUMENTACIÓN CONTABLE",Checklist!$D$8:$D$75,"Sí") | D12: =COUNTIFS(Checklist!$B$8:$B$75,"DOCUMENTACIÓN CONTABLE",Checklist!$D$8:$D$75,"Parcial") | E12: =COUNTIFS(Checklist!$B$8:$B$75,"DOCUMENTACIÓN CONTABLE",Checklist!$D$8:$D$75,"No") | F12: =IFERROR((C12+D12/2)/B12,0)
A13: Documentos del colegio | B13: =COUNTIFS(Checklist!$B$8:$B$75,"DOCUMENTOS DEL COLEGIO",Checklist!$C$8:$C$75,"<>") | C13: =COUNTIFS(Checklist!$B$8:$B$75,"DOCUMENTOS DEL COLEGIO",Checklist!$D$8:$D$75,"Sí") | D13: =COUNTIFS(Checklist!$B$8:$B$75,"DOCUMENTOS DEL COLEGIO",Checklist!$D$8:$D$75,"Parcial") | E13: =COUNTIFS(Checklist!$B$8:$B$75,"DOCUMENTOS DEL COLEGIO",Checklist!$D$8:$D$75,"No") | F13: =IFERROR((C13+D13/2)/B13,0)
A14: TOTAL | B14: =SUM(B10:B13) | C14: =SUM(C10:C13) | D14: =SUM(D10:D13) | E14: =SUM(E10:E13) | F14: =IFERROR((C14+D14/2)/B14,0)
A16: CÓMO LEERLO
A17: Sí | B17: El catálogo de Cumplimiento ya tiene un concepto que cubre el documento; se gestiona en Registro de Cumplimiento.
A18: Parcial | B18: Hay un concepto relacionado, pero no es el mismo documento o lo cubre solo en parte (ver columna "Concepto del catálogo").
A19: No | B19: No existe en el catálogo. La columna "Sugerencia" indica si conviene agregarlo a Cumplimiento o si pertenece a otra área.
A21: Fuente: "Relación Documentos para Convocatorias" (hoja Documentación) y Catálogo de Cumplimiento del Sistema RCMA (61 conceptos activos al 28/10/2026). La columna "¿En el sistema?" se puede cambiar y todo el resumen se recalcula.
A23: Colegios Mano Amiga — Juntos Transformando Vidas. | D23: Checklist Convocatorias · Cumplimiento · Sistema RCMA

Sheet Checklist
A1: RED DE COLEGIOS MANO AMIGA · CUMPLIMIENTO NORMATIVO
A2: CHECKLIST · DOCUMENTOS PARA CONVOCATORIAS
A3: ¿Lo tengo en el módulo de Cumplimiento? · Cruce documento por documento
A6: Estatus: Sí = ya está en el catálogo · Parcial = hay un concepto relacionado · No = no está. Las celdas en crema se pueden editar.
A7: No. | B7: Categoría | C7: Documento que pide la convocatoria | D7: ¿En el sistema? | E7: Concepto del catálogo de Cumplimiento | F7: Materia | G7: Periodicidad | H7: Sugerencia | I7: Observaciones
A8: DOCUMENTACIÓN LEGAL
A9: 1 | B9: DOCUMENTACIÓN LEGAL | C9: Acta constitutiva | D9: Sí | E9: #22 Acta Constitutiva de la Sociedad / Asociación | F9: Jurídico | G9: Fijo | H9: Ya está en Cumplimiento
A10: 2 | B10: DOCUMENTACIÓN LEGAL | C10: Protocolizaciones | D10: Parcial | E10: #22 Acta Constitutiva de la Sociedad / Asociación | F10: Jurídico | G10: Fijo | H10: Agregar al catálogo CN | I10: Hoy van dentro del Acta Constitutiva; cambian con cada nuevo Director o Administrador.
A11: 3 | B11: DOCUMENTACIÓN LEGAL | C11: Poder del Representante Legal | D11: Sí | E11: #26 Poder Notarial del Representante Legal | F11: Jurídico | G11: Fijo | H11: Ya está en Cumplimiento
A12: 4 | B12: DOCUMENTACIÓN LEGAL | C12: Identificación Oficial del Representante Legal | D12: Sí | E12: #25 Identificación Oficial del Representante Legal | F12: Jurídico | G12: Fijo | H12: Ya está en Cumplimiento
A13: 5 | B13: DOCUMENTACIÓN LEGAL | C13: Programa o Protocolo Interno de Protección Civil | D13: Sí | E13: #40 Programa Interno de Protección Civil (PIPC) | F13: Protección Civil | G13: Anual | H13: Ya está en Cumplimiento
A14: 6 | B14: DOCUMENTACIÓN LEGAL | C14: Constancia de Actividades Sociales (vigente) | D14: No | E14: — | G14: Fijo | H14: Agregar al catálogo CN
A15: 7 | B15: DOCUMENTACIÓN LEGAL | C15: CURP del Representante Legal | D15: No | E15: — | G15: Fijo | H15: Agregar al catálogo CN | I15: Podría ir junto con la Identificación Oficial (#25).
A16: 8 | B16: DOCUMENTACIÓN LEGAL | C16: RFC del Representante Legal | D16: No | E16: — | G16: Fijo | H16: Agregar al catálogo CN | I16: Podría ir junto con la Identificación Oficial (#25).
A17: 9 | B17: DOCUMENTACIÓN LEGAL | C17: Inscripción al Registro Público | D17: Parcial | E17: #22 Acta Constitutiva de la Sociedad / Asociación | F17: Jurídico | G17: Fijo | H17: Ya está en Cumplimiento | I17: Normalmente viene dentro del Acta Constitutiva.
A18: 10 | B18: DOCUMENTACIÓN LEGAL | C18: Número de Registro Patronal | D18: Sí | E18: #13 Registro Patronal IMSS con Grado de Riesgo | F18: Gestión de Riesgos | G18: Fijo | H18: Ya está en Cumplimiento
A19: DOCUMENTACIÓN FISCAL
A20: 1 | B20: DOCUMENTACIÓN FISCAL | C20: RI - Inscripción al SAT | D20: Parcial | E20: #7 Constancia de Situación Fiscal (RFC) | F20: Fiscal | G20: Fijo | H20: Ya está en Cumplimiento | I20: La Constancia de Situación Fiscal cubre los datos de inscripción.
A21: 2 | B21: DOCUMENTACIÓN FISCAL | C21: Cédula Fiscal (RFC del Colegio) | D21: Sí | E21: #7 Constancia de Situación Fiscal (RFC) | F21: Fiscal | G21: Fijo | H21: Ya está en Cumplimiento
A22: 3 | B22: DOCUMENTACIÓN FISCAL | C22: Constancia de Situación Fiscal (vigente) | D22: Sí | E22: #7 Constancia de Situación Fiscal (RFC) | F22: Fiscal | G22: Mensual | H22: Ya está en Cumplimiento
A23: 4 | B23: DOCUMENTACIÓN FISCAL | C23: Opinión de Cumplimiento SAT (vigente) | D23: Sí | E23: #8 Opinión de Cumplimiento de Obligaciones Fiscales (32-D) | F23: Fiscal | G23: Mensual | H23: Ya está en Cumplimiento
A24: 5 | B24: DOCUMENTACIÓN FISCAL | C24: Última publicación en el DOF, Anexo 14 (anual) | D24: No | E24: — | G24: Anual | H24: Agregar al catálogo CN | I24: Materia Donatarias.
A25: 6 | B25: DOCUMENTACIÓN FISCAL | C25: Documento de autorización de donataria expedida por el SAT/SHCP | D25: No | E25: — | G25: Fijo | H25: Agregar al catálogo CN | I25: Materia Donatarias.
A26: 7 | B26: DOCUMENTACIÓN FISCAL | C26: Carta de Donataria actualizada del SAT | D26: No | E26: — | G26: Fijo | H26: Agregar al catálogo CN | I26: Materia Donatarias.
A27: 8 | B27: DOCUMENTACIÓN FISCAL | C27: Autorización de SAT desde su origen | D27: No | E27: — | G27: Fijo | H27: Agregar al catálogo CN | I27: Materia Donatarias.
A28: 9 | B28: DOCUMENTACIÓN FISCAL | C28: Prevención de antilavado de dinero (formato y documentación del donante) | D28: Parcial | E28: #10 Aviso de Privacidad Integral (LFPDPPP) (Ley Antilavado) | F28: Fiscal / Comercial | G28: Anual | H28: Agregar al catálogo CN | I28: El concepto #10 menciona Ley Antilavado junto con Aviso de Privacidad; el formato del donante no está separado.
A29: 10 | B29: DOCUMENTACIÓN FISCAL | C29: Validación para recibir donativos del extranjero | D29: No | E29: — | G29: Fijo | H29: Agregar al catálogo CN | I29: Materia Donatarias.
A30: 11 | B30: DOCUMENTACIÓN FISCAL | C30: Carta de Acreditación de Actividades SAT (modificación de estatutos) | D30: No | E30: — | G30: Fijo | H30: Agregar al catálogo CN | I30: Materia Donatarias.
A31: DOCUMENTACIÓN CONTABLE
A32: 1 | B32: DOCUMENTACIÓN CONTABLE | C32: Carátula Bancaria (mensual) | D32: No | E32: — | G32: Mensual | H32: Fuera de CN · Contabilidad / Finanzas
A33: 2 | B33: DOCUMENTACIÓN CONTABLE | C33: Estados Financieros (año anterior) | D33: No | E33: — | G33: Anual | H33: Fuera de CN · Contabilidad / Finanzas
A34: 3 | B34: DOCUMENTACIÓN CONTABLE | C34: Declaración Anual (año anterior) | D34: No | E34: — | G34: Anual | H34: Fuera de CN · Contabilidad / Finanzas | I34: Si se quiere en CN, iría en materia Fiscal.
A35: 4 | B35: DOCUMENTACIÓN CONTABLE | C35: Balanza de comprobación (año anterior) | D35: No | E35: — | G35: Anual | H35: Fuera de CN · Contabilidad / Finanzas
A36: 5 | B36: DOCUMENTACIÓN CONTABLE | C36: Balanza General (año anterior) | D36: No | E36: — | G36: Anual | H36: Fuera de CN · Contabilidad / Finanzas
A37: 6 | B37: DOCUMENTACIÓN CONTABLE | C37: Informe de Actividades (año en curso) | D37: No | E37: — | G37: Anual | H37: Fuera de CN · Contabilidad / Finanzas
A38: 7 | B38: DOCUMENTACIÓN CONTABLE | C38: Presupuesto Anual del año en curso (ingresos - egresos) | D38: No | E38: — | G38: Anual | H38: Fuera de CN · Contabilidad / Finanzas
A39: 8 | B39: DOCUMENTACIÓN CONTABLE | C39: Último Presupuesto anual presentado a la Junta de Asistencia Privada (MA Cima, FIADES y FSA) | D39: No | E39: — | G39: Anual | H39: Fuera de CN · Contabilidad / Finanzas | I39: Solo aplica a MA Cima, FIADES y FSA.
A40: 9 | B40: DOCUMENTACIÓN CONTABLE | C40: Último Informe anual presentado a la Junta de Asistencia Privada (MA Cima, FIADES y FSA) | D40: No | E40: — | G40: Anual | H40: Fuera de CN · Contabilidad / Finanzas | I40: Solo aplica a MA Cima, FIADES y FSA.
A41: DOCUMENTOS DEL COLEGIO
A42: 1 | B42: DOCUMENTOS DEL COLEGIO | C42: Licencia de Funcionamiento | D42: Sí | E42: #17 Licencia de Funcionamiento Municipal | F42: Inmobiliaria | G42: Anual | H42: Ya está en Cumplimiento
...

Sheet Catálogo CN
A1: RED DE COLEGIOS MANO AMIGA · CUMPLIMIENTO NORMATIVO
A2: CATÁLOGO DE CUMPLIMIENTO
A3: Conceptos activos en el Sistema RCMA (61) · ¿cuáles pide la convocatoria?
A6: # | B6: Concepto | C6: Materia | D6: Periodicidad | E6: ¿Lo pide la convocatoria? | F6: Documento de la convocatoria
A7: 1 | B7: Acuerdo de Incorporación RVOE Iniciales | C7: Donatarias / RVOE | D7: Único trámite | E7: Sí | F7: RVOEs (todas las secciones del colegio)
A8: 2 | B8: Convenio de Apoyo Económico | C8: Donatarias / RVOE | D8: Anual | E8: Sí | F8: Documentos de convenios (empresas o universidades)
A9: 3 | B9: Refrendo de Incorporación de RVOE | C9: Donatarias / RVOE | D9: Anual | E9: Sí | F9: RVOEs (todas las secciones del colegio)
A10: 4 | B10: Planta Docente y Directiva (Títulos y Cédulas) | C10: Donatarias / RVOE | D10: Anual | E10: Sí | F10: Número de docentes y administrativos por género
A11: 5 | B11: Planes, Programas de Estudio y Horarios | C11: Donatarias / RVOE | D11: Anual | E11: Sí | F11: Mapa curricular (asignaturas por grado escolar) · Programas del colegio (SEP y modelo educativo)
A12: 6 | B12: Reglamento Escolar Interno | C12: Donatarias / RVOE | D12: Anual | E12: Sí | F12: Reglamento Interno
A13: 7 | B13: Constancia de Situación Fiscal (RFC) | C13: Fiscal | D13: Trimestral | E13: Sí | F13: RI - Inscripción al SAT · Cédula Fiscal (RFC del Colegio) · Constancia de Situación Fiscal (vigente)
A14: 8 | B14: Opinión de Cumplimiento de Obligaciones Fiscales (32-D) | C14: Fiscal | D14: Mensual | E14: Sí | F14: Opinión de Cumplimiento SAT (vigente)
A15: 9 | B15: Contrato de Adhesión (PROFECO) | C15: Fiscal / Comercial | D15: Único trámite | E15: No
A16: 10 | B16: Aviso de Privacidad Integral (LFPDPPP) (Ley Antilavado) | C16: Fiscal / Comercial | D16: Único trámite | E16: Sí | F16: Prevención de antilavado de dinero (formato y documentación del donante) · Aviso de Privacidad
A17: 12 | B17: Póliza de Seguro Escolar (Alumnos) | C17: Gestión de Riesgos | D17: Anual | E17: No
A18: 13 | B18: Registro Patronal IMSS con Grado de Riesgo | C18: Gestión de Riesgos | D18: Único trámite | E18: Sí | F18: Número de Registro Patronal
A19: 14 | B19: Seguro de Inmuebles y Contenidos | C19: Gestión de Riesgos | D19: Anual | E19: No
A20: 15 | B20: Seguro de Responsabilidad Civil Generación/Terceros | C20: Gestión de Riesgos | D20: Anual | E20: No
A21: 16 | B21: Comprobante de Domicilio (CFE o Agua) | C21: Inmobiliaria | D21: Mensual | E21: Sí | F21: Comprobante de domicilio (vigente)
A22: 17 | B22: Licencia de Funcionamiento Municipal | C22: Inmobiliaria | D22: Anual | E22: Sí | F22: Licencia de Funcionamiento
A23: 18 | B23: Boleta Predial Vigente | C23: Inmobiliaria | D23: Anual | E23: Sí | F23: Predial
A24: 19 | B24: Dictamen / Licencia de Uso de Suelo Educativo | C24: Inmobiliaria | D24: Único trámite | E24: Sí | F24: Uso de suelo
A25: 20 | B25: Licencia de Anuncios y Publicidad Exterior | C25: Inmobiliaria | D25: Anual | E25: No
A26: 21 | B26: Evaluación de Impacto Estatal (COIME) | C26: Inmobiliaria | D26: Único trámite | E26: No
A27: 22 | B27: Acta Constitutiva de la Sociedad / Asociación | C27: Jurídico | D27: Único trámite | E27: Sí | F27: Acta constitutiva · Protocolizaciones · Inscripción al Registro Público
A28: 23 | B28: Contrato de Comodato o Arrendamiento | C28: Jurídico | D28: Único trámite | E28: Sí | F28: Contrato de Comodato (si aplica)
A29: 24 | B29: Escrituras del Inmueble | C29: Jurídico | D29: Único trámite | E29: No
A30: 25 | B30: Identificación Oficial del Representante Legal | C30: Jurídico | D30: Cada 10 años | E30: Sí | F30: Identificación Oficial del Representante Legal
A31: 26 | B31: Poder Notarial del Representante Legal | C31: Jurídico | D31: Único trámite | E31: Sí | F31: Poder del Representante Legal
A32: 27 | B32: Reglamento Interior de Trabajo Depositado | C32: Jurídico | D32: Único trámite | E32: No
A33: 28 | B33: Constancia de Seguridad Estructural (DRO) | C33: Construcción | D33: Anual | E33: No
A34: 29 | B34: Memoria de Cálculo y Planos As-Built | C34: Construcción | D34: Único trámite | E34: No
A35: 30 | B35: Comité Interno de Protección Civil | C35: Protección Civil | D35: Anual | E35: No
A36: 31 | B36: Cronograma de Mantenimiento en Instalaciones | C36: Protección Civil | D36: Anual | E36: No
A37: 32 | B37: Diagrama Unifilar de Instalaciones Eléctricas | C37: Protección Civil | D37: Anual | E37: No
A38: 33 | B38: Dictamen de Gas (LP / Natural) | C38: Protección Civil | D38: Anual | E38: No
A39: 34 | B39: Dictamen Eléctrico (UVIE) | C39: Protección Civil | D39: Anual | E39: No
A40: 35 | B40: Plan de Continuidad de Operaciones | C40: Protección Civil | D40: Anual | E40: No
A41: 36 | B41: Plano: Accesibilidad para Personas con Discapacidad | C41: Protección Civil | D41: Anual | E41: No
A42: 37 | B42: Plano: Cajones de Estacionamiento y Ascenso/Descenso | C42: Protección Civil | D42: Anual | E42: No
...
