Workbook

Sheet Instrucciones
A1: RED DE COLEGIOS MANO AMIGA · PROGRAMA SOL
A2: INSTRUCCIONES DE USO
A3: Formato de Inspección SOL · Clave: SOL-F01 · Versión 1.2
B6: FORMATO VIGENTE
B7: SOL-F01 · Versión 1.2 · 33 criterios en 8 áreas · vigente desde 28/10/2026
B9: CÓMO LLENAR EL FORMATO
B10: 1 | C10: En la hoja Inspección elige el Campus y el Tipo de inspección de las listas; captura la fecha y los inspectores. El territorio se llena solo.
B11: 2 | C11: Escribe el nombre del dueño en el renglón azul de cada área.
B12: 3 | C12: Recorre las 8 áreas y califica cada criterio: 2 = Cumple · 1 = Cumple parcialmente · 0 = No cumple · NA = No aplica (por ejemplo, un campus sin laboratorio).
B13: 4 | C13: Todo criterio con 0 o 1 lleva observación y foto. Regístralo en la hoja Hallazgos con responsable y fecha compromiso.
B14: 5 | C14: La hoja Resultado calcula sola el Índice SOL (0–100), el % por área y por componente S · O · L, con semáforo.
B15: 6 | C15: Los artículos que no se necesitan se marcan con tarjeta roja y se registran en la hoja Tarjeta Roja; su destino se decide en máximo 30 días.
B16: 7 | C16: Imprime o guarda en PDF las hojas Inspección y Resultado, fírmalas y envíalas a la Coordinación RCMA junto con las fotos.
B17: 8 | C17: SOL revisa hábitos: que todo esté despejado, ordenado y limpio. El estado del inmueble (instalaciones, fugas, daños) no se califica aquí: se reporta a Mantenimiento con Ticket MAS.
B19: SEMÁFORO DEL ÍNDICE SOL
B20: VERDE | C20: 85 a 100 · Campus SOL: candidato al distintivo anual
B21: ÁMBAR | C21: 70 a 84 · En mejora: hallazgos con fecha de cierre
B22: ROJO | C22: 0 a 69 · Plan de acción: acompañamiento del territorio
B24: Frecuencia: semanal (Comité SOL) · mensual (Director de campus) · trimestral (auditoría cruzada) · anual (verificación NOM-001-STPS-2008). Las celdas de captura están desbloqueadas; el resto está protegido para que el Sistema RCMA pueda leer el archivo. No agregues ni muevas filas o columnas.
A26: Colegios Mano Amiga — Juntos Transformando Vidas. | D26: SOL-F01 · v1.2 · Sistema RCMA

Sheet Inspección
A1: RED DE COLEGIOS MANO AMIGA · PROGRAMA SOL
A2: FORMATO DE INSPECCIÓN SOL
A3: Seguridad · Orden · Limpieza — Clave: SOL-F01 · Versión 1.2
A5: CLAVE | D5: VERSIÓN | E5: CRITERIOS | F5: ÁREAS
A6: SOL-F01 | D6: v1.2 · vigente desde 28/10/2026 | E6: 33 | F6: 8 áreas · S · O · L
A8: DATOS DE LA INSPECCIÓN
A9: Campus | E9: Territorio | F9: =IFERROR(VLOOKUP(C9,Listas!$A$2:$B$21,2,FALSE),"")
A10: Fecha de inspección | E10: Tipo de inspección
A11: Inspector(es) | E11: Director de campus
A13: Escala: 2 = Cumple · 1 = Cumple parcialmente · 0 = No cumple · NA = No aplica. Tipo: S = Seguridad · O = Orden · L = Limpieza. Todo 0 o 1 se registra en la hoja Hallazgos.
A14: No. | B14: Área | C14: Tipo | D14: Criterio a verificar | E14: Calificación | F14: Observación / hallazgo | G14: ¿Foto?
A15: AULAS · Dueño del área: ______________________________
A16: 1 | B16: Aulas | C16: S | D16: Salida y pasillos libres de obstáculos; la puerta abre sin obstrucción
A17: 2 | B17: Aulas | C17: S | D17: Sin extensiones improvisadas ni cables en el paso; daños reportados a Mantenimiento
A18: 3 | B18: Aulas | C18: O | D18: Mobiliario acomodado; nada fuera de lugar
A19: 4 | B19: Aulas | C19: O | D19: Material didáctico guardado y rotulado
A20: 5 | B20: Aulas | C20: L | D20: Piso, pizarrón, ventanas y mobiliario limpios; basura en su contenedor
A21: BAÑOS · Dueño del área: ______________________________
A22: 6 | B22: Baños | C22: S | D22: Pisos secos; fugas reportadas a Mantenimiento
A23: 7 | B23: Baños | C23: O | D23: Insumos (papel, jabón) abastecidos y en su lugar
A24: 8 | B24: Baños | C24: L | D24: Sanitarios, lavabos y espejos limpios, sin malos olores
A25: 9 | B25: Baños | C25: L | D25: Bitácora de limpieza visible y al día
A26: COCINA Y CAFETERÍA · Dueño del área: ______________________________
A27: 10 | B27: Cocina y cafetería | C27: S | D27: Extintor visible y sin obstrucciones; área de gas despejada
A28: 11 | B28: Cocina y cafetería | C28: S | D28: Químicos de limpieza separados de los alimentos
A29: 12 | B29: Cocina y cafetería | C29: O | D29: Utensilios y alimentos en su lugar, rotulados y con fecha
A30: 13 | B30: Cocina y cafetería | C30: L | D30: Superficies, campana y equipo limpios
A31: BODEGAS · Dueño del área: ______________________________
A32: 14 | B32: Bodegas | C32: S | D32: Estibas estables, material pesado abajo; sin acceso de alumnos
A33: 15 | B33: Bodegas | C33: S | D33: Sustancias químicas rotuladas y con hoja de seguridad
A34: 16 | B34: Bodegas | C34: O | D34: Estantes rotulados; cada cosa en su lugar
A35: 17 | B35: Bodegas | C35: O | D35: Sin material obsoleto (tarjetas rojas atendidas)
A36: 18 | B36: Bodegas | C36: L | D36: Piso y estantes limpios, sin plagas
A37: CUARTOS TÉCNICOS · Dueño del área: ______________________________
A38: 19 | B38: Cuartos técnicos | C38: S | D38: Acceso restringido; área despejada frente al tablero, sin materiales almacenados
A39: 20 | B39: Cuartos técnicos | C39: L | D39: Área limpia, sin polvo ni basura acumulada
A40: PATIOS Y RUTAS DE EVACUACIÓN · Dueño del área: ______________________________
A41: 21 | B41: Patios y rutas de evacuación | C41: S | D41: Rutas y salidas de emergencia libres de obstáculos
A42: 22 | B42: Patios y rutas de evacuación | C42: O | D42: Mobiliario exterior y equipo deportivo guardado
A43: 23 | B43: Patios y rutas de evacuación | C43: L | D43: Patios y áreas verdes limpios; basura en sus contenedores
...

Sheet Resultado
A1: RED DE COLEGIOS MANO AMIGA · PROGRAMA SOL
A2: RESULTADO · ÍNDICE SOL
A3: Se calcula solo con la hoja Inspección · SOL-F01 · v1.2
A5: CAMPUS | B5: FECHA | D5: TIPO DE INSPECCIÓN
A6: =IF(Inspección!C9="","—",Inspección!C9) | B6: =IF(Inspección!C10="","—",TEXT(Inspección!C10,"dd/mm/yyyy")) | D6: =IF(Inspección!F10="","—",Inspección!F10)
A8: ÍNDICE SOL | B8: PUNTOS OBTENIDOS ÷ POSIBLES × 100 | D8: =IF(B9="","Sin calificar",IF(B9>=85,"VERDE · Campus SOL",IF(B9>=70,"ÁMBAR · En mejora","ROJO · Plan de acción")))
B9: =IFERROR(ROUND(SUM(Inspección!$E$15:$E$55)/(2*COUNT(Inspección!$E$15:$E$55))*100,1),"")
B10: =33-COUNT(Inspección!$E$15:$E$55)-COUNTIF(Inspección!$E$15:$E$55,"NA")&" de 33 criterios sin calificar"
A12: RESULTADO POR ÁREA
A13: Área | B13: Puntos obtenidos | C13: Puntos posibles | D13: % cumplimiento | E13: Semáforo
A14: Aulas | B14: =SUMIFS(Inspección!$E$15:$E$55,Inspección!$B$15:$B$55,"Aulas") | C14: =2*COUNTIFS(Inspección!$B$15:$B$55,"Aulas",Inspección!$E$15:$E$55,">=0") | D14: =IF(C14=0,"",B14/C14) | E14: =IF(D14="","—",IF(D14>=0.85,"Verde",IF(D14>=0.7,"Ámbar","Rojo")))
A15: Baños | B15: =SUMIFS(Inspección!$E$15:$E$55,Inspección!$B$15:$B$55,"Baños") | C15: =2*COUNTIFS(Inspección!$B$15:$B$55,"Baños",Inspección!$E$15:$E$55,">=0") | D15: =IF(C15=0,"",B15/C15) | E15: =IF(D15="","—",IF(D15>=0.85,"Verde",IF(D15>=0.7,"Ámbar","Rojo")))
A16: Cocina y cafetería | B16: =SUMIFS(Inspección!$E$15:$E$55,Inspección!$B$15:$B$55,"Cocina y cafetería") | C16: =2*COUNTIFS(Inspección!$B$15:$B$55,"Cocina y cafetería",Inspección!$E$15:$E$55,">=0") | D16: =IF(C16=0,"",B16/C16) | E16: =IF(D16="","—",IF(D16>=0.85,"Verde",IF(D16>=0.7,"Ámbar","Rojo")))
A17: Bodegas | B17: =SUMIFS(Inspección!$E$15:$E$55,Inspección!$B$15:$B$55,"Bodegas") | C17: =2*COUNTIFS(Inspección!$B$15:$B$55,"Bodegas",Inspección!$E$15:$E$55,">=0") | D17: =IF(C17=0,"",B17/C17) | E17: =IF(D17="","—",IF(D17>=0.85,"Verde",IF(D17>=0.7,"Ámbar","Rojo")))
A18: Cuartos técnicos | B18: =SUMIFS(Inspección!$E$15:$E$55,Inspección!$B$15:$B$55,"Cuartos técnicos") | C18: =2*COUNTIFS(Inspección!$B$15:$B$55,"Cuartos técnicos",Inspección!$E$15:$E$55,">=0") | D18: =IF(C18=0,"",B18/C18) | E18: =IF(D18="","—",IF(D18>=0.85,"Verde",IF(D18>=0.7,"Ámbar","Rojo")))
A19: Patios y rutas de evacuación | B19: =SUMIFS(Inspección!$E$15:$E$55,Inspección!$B$15:$B$55,"Patios y rutas de evacuación") | C19: =2*COUNTIFS(Inspección!$B$15:$B$55,"Patios y rutas de evacuación",Inspección!$E$15:$E$55,">=0") | D19: =IF(C19=0,"",B19/C19) | E19: =IF(D19="","—",IF(D19>=0.85,"Verde",IF(D19>=0.7,"Ámbar","Rojo")))
A20: Oficinas | B20: =SUMIFS(Inspección!$E$15:$E$55,Inspección!$B$15:$B$55,"Oficinas") | C20: =2*COUNTIFS(Inspección!$B$15:$B$55,"Oficinas",Inspección!$E$15:$E$55,">=0") | D20: =IF(C20=0,"",B20/C20) | E20: =IF(D20="","—",IF(D20>=0.85,"Verde",IF(D20>=0.7,"Ámbar","Rojo")))
A21: Laboratorios y talleres | B21: =SUMIFS(Inspección!$E$15:$E$55,Inspección!$B$15:$B$55,"Laboratorios y talleres") | C21: =2*COUNTIFS(Inspección!$B$15:$B$55,"Laboratorios y talleres",Inspección!$E$15:$E$55,">=0") | D21: =IF(C21=0,"",B21/C21) | E21: =IF(D21="","—",IF(D21>=0.85,"Verde",IF(D21>=0.7,"Ámbar","Rojo")))
A23: RESULTADO POR COMPONENTE
A24: Componente | B24: Puntos obtenidos | C24: Puntos posibles | D24: % cumplimiento | E24: Semáforo
A25: S · Seguridad | B25: =SUMIFS(Inspección!$E$15:$E$55,Inspección!$C$15:$C$55,"S") | C25: =2*COUNTIFS(Inspección!$C$15:$C$55,"S",Inspección!$E$15:$E$55,">=0") | D25: =IF(C25=0,"",B25/C25) | E25: =IF(D25="","—",IF(D25>=0.85,"Verde",IF(D25>=0.7,"Ámbar","Rojo")))
A26: O · Orden | B26: =SUMIFS(Inspección!$E$15:$E$55,Inspección!$C$15:$C$55,"O") | C26: =2*COUNTIFS(Inspección!$C$15:$C$55,"O",Inspección!$E$15:$E$55,">=0") | D26: =IF(C26=0,"",B26/C26) | E26: =IF(D26="","—",IF(D26>=0.85,"Verde",IF(D26>=0.7,"Ámbar","Rojo")))
A27: L · Limpieza | B27: =SUMIFS(Inspección!$E$15:$E$55,Inspección!$C$15:$C$55,"L") | C27: =2*COUNTIFS(Inspección!$C$15:$C$55,"L",Inspección!$E$15:$E$55,">=0") | D27: =IF(C27=0,"",B27/C27) | E27: =IF(D27="","—",IF(D27>=0.85,"Verde",IF(D27>=0.7,"Ámbar","Rojo")))
A29: Rangos: Verde 85–100 (Campus SOL) · Ámbar 70–84 (En mejora) · Rojo 0–69 (Plan de acción). NA no suma ni resta.
A31: Colegios Mano Amiga — Juntos Transformando Vidas. | D31: SOL-F01 · v1.2 · Sistema RCMA

Sheet Hallazgos
A1: RED DE COLEGIOS MANO AMIGA · PROGRAMA SOL
A2: PLAN DE ACCIÓN · HALLAZGOS SOL
A3: Todo criterio calificado 0 o 1 se registra aquí con responsable y fecha · SOL-F01 · v1.2
A6: No. | B6: Fecha | C6: Área | D6: Tipo | E6: Hallazgo | F6: Acción correctiva | G6: Responsable | H6: Fecha compromiso | I6: ¿Requiere Ticket? | J6: Folio Ticket | K6: Estatus | L6: Fecha de cierre | M6: Días abierto
A7: 1 | M7: =IF(B7="","",IF(L7<>"",L7-B7,TODAY()-B7))
A8: 2 | M8: =IF(B8="","",IF(L8<>"",L8-B8,TODAY()-B8))
A9: 3 | M9: =IF(B9="","",IF(L9<>"",L9-B9,TODAY()-B9))
A10: 4 | M10: =IF(B10="","",IF(L10<>"",L10-B10,TODAY()-B10))
A11: 5 | M11: =IF(B11="","",IF(L11<>"",L11-B11,TODAY()-B11))
A12: 6 | M12: =IF(B12="","",IF(L12<>"",L12-B12,TODAY()-B12))
A13: 7 | M13: =IF(B13="","",IF(L13<>"",L13-B13,TODAY()-B13))
A14: 8 | M14: =IF(B14="","",IF(L14<>"",L14-B14,TODAY()-B14))
A15: 9 | M15: =IF(B15="","",IF(L15<>"",L15-B15,TODAY()-B15))
A16: 10 | M16: =IF(B16="","",IF(L16<>"",L16-B16,TODAY()-B16))
A17: 11 | M17: =IF(B17="","",IF(L17<>"",L17-B17,TODAY()-B17))
A18: 12 | M18: =IF(B18="","",IF(L18<>"",L18-B18,TODAY()-B18))
... A36: 30 | M36: =IF(B36="","",IF(L36<>"",L36-B36,TODAY()-B36))
A38: =COUNTIF(K7:K36,"Cerrado")&" de "&COUNTA(E7:E36)&" hallazgos cerrados · Meta: cerrar en menos de 30 días"
A40: Colegios Mano Amiga — Juntos Transformando Vidas. | G40: SOL-F01 · v1.2 · Sistema RCMA

Sheet Tarjeta Roja
A1: RED DE COLEGIOS MANO AMIGA · PROGRAMA SOL
A2: REGISTRO DE TARJETAS ROJAS
A3: Artículos identificados en la etapa Clasificar: su destino se decide en máximo 30 días · SOL-F01 · v1.2
A6: Folio | B6: Fecha | C6: Área | D6: Artículo / material | E6: Cantidad | F6: Motivo | G6: Destino | H6: Responsable | I6: Fecha límite | J6: Estatus | K6: Observaciones
A7: TR-001
A8: TR-002
A9: TR-003
A10: TR-004
A11: TR-005
A12: TR-006
A13: TR-007
A14: TR-008
A15: TR-009
A16: TR-010
A17: TR-011
A18: TR-012
... A36: TR-030
A38: Colegios Mano Amiga — Juntos Transformando Vidas. | H38: SOL-F01 · v1.2 · Sistema RCMA

Sheet Listas
A1: Campus | B1: Territorio | D1: Tipo de inspección | F1: Áreas
A2: Mano Amiga Aguascalientes | B2: NORTE | D2: Semanal · Comité SOL | F2: Aulas
A3: Mano Amiga Guadalajara | B3: NORTE | D3: Mensual · Director de campus | F3: Baños
A4: Mano Amiga La Cima | B4: NORTE | D4: Trimestral · Auditoría cruzada | F4: Cocina y cafetería
A5: Mano Amiga León | B5: NORTE | D5: Anual · Verificación NOM-001-STPS | F5: Bodegas
A6: Mano Amiga Monterrey | B6: NORTE | D6: Línea base | F6: Cuartos técnicos
A7: Mano Amiga Piedras Negras | B7: NORTE | F7: Patios y rutas de evacuación
A8: Mano Amiga Santa Catarina | B8: NORTE | F8: Oficinas
A9: Mano Amiga Tijuana | B9: NORTE | F9: Laboratorios y talleres
A10: Mano Amiga Torreón | B10: NORTE
A11: Mano Amiga Villas de San Juan | B11: NORTE
A12: Mano Amiga Acapulco | B12: MÉXICO
A13: Mano Amiga Cancún | B13: MÉXICO
A14: Mano Amiga Chalco | B14: MÉXICO
A15: Mano Amiga Conkal | B15: MÉXICO
A16: Mano Amiga Lerma | B16: MÉXICO
A17: Mano Amiga Morelia | B17: MÉXICO
A18: Mano Amiga Puebla | B18: MÉXICO
A19: Mano Amiga Querétaro | B19: MÉXICO
A20: Mano Amiga Tapachula | B20: MÉXICO
A21: Mano Amiga Zomeyucan | B21: MÉXICO
